Workbook

Sheet Read me
A1: How to translate: fill the 'translation' column. Leave it empty to keep the English.
A2: Each row is one unique English text (per tab); 'uses' = how many game entries share it, all get your translation.
A3: Do not edit file / label (first entry using the text). location / speaker are guesses from the label name.
A4: Entries with nothing to translate (only codes or symbols) are left out and stay as they are.
A6: Codes inside the text:
A7: line break = a real line break in the cell (Alt+Enter in Excel)
A8: [p] = new page (waits for a button press)
A9: [s] = scroll one line
A10: [0] [1] ... = placeholders (player name, Pokémon, item, number...). Move them freely, keep them.
A11: [w:0.2] [e:4] = pauses / timed effects. Keep them.
A12: <color=...>...</color>, <size=...>, <pos=...> = text formatting. Keep them.
A13: {ele|ela} = depends on the PLAYER's gender: male text | female text. Ex: Você é um{|a} ótim{o|a} Treinador{|a}!
... A17: [[ and {{ = a literal [ or { character.

Sheet Names
A1: file | B1: label | C1: location | D1: speaker | E1: english | F1: translation | G1: uses
A2: english_dp_underground_name_plural_classified | B2: UNDERGROUND_NAME_001 | E2: Red Spheres S | F2: Esferas Vermelhas P | G2: 3
A3: english_dp_underground_name_plural_classified | B3: UNDERGROUND_NAME_002 | E3: Blue Spheres S | F3: Esferas Azuis P | G3: 2
A4: english_dp_underground_name_plural_classified | B4: UNDERGROUND_NAME_003 | E4: Green Spheres S | F4: Esferas Verdes P | G4: 2
A5: english_dp_underground_name_plural_classified | B5: UNDERGROUND_NAME_004 | E5: Prism Spheres S | F5: Esferas Prismáticas P | G5: 2
A6: english_dp_underground_name_plural_classified | B6: UNDERGROUND_NAME_005 | E6: Pale Spheres S | F6: Esferas Pálidas P | G6: 2
A7: english_dp_underground_name_plural_classified | B7: UNDERGROUND_NAME_006 | E7: Red Spheres L | F7: Esferas Vermelhas G | G7: 2
A8: english_dp_underground_name_plural_classified | B8: UNDERGROUND_NAME_007 | E8: Blue Spheres L | F8: Esferas Azuis G | G8: 2
A9: english_dp_underground_name_plural_classified | B9: UNDERGROUND_NAME_008 | E9: Green Spheres L | F9: Esferas Verdes G | G9: 2
A10: english_dp_underground_name_plural_classified | B10: UNDERGROUND_NAME_009 | E10: Prism Spheres L | F10: Esferas Prismáticas G | G10: 2
A11: english_dp_underground_name_plural_classified | B11: UNDERGROUND_NAME_010 | E11: Pale Spheres L | F11: Esferas Pálidas G | G11: 2
A12: english_dp_underground_name_plural_classified | B12: UNDERGROUND_NAME_011 | E12: Revives | F12: Reviveres | G12: 4
A13: english_dp_underground_name_plural_classified | B13: UNDERGROUND_NAME_012 | E13: Max Revives | F13: Reviveres Máx. | G13: 4
... A106: english_dp_underground_name_plural_classified | B106: UNDERGROUND_NAME_399 | E106: Digger Drills | F106: Brocas Escavadoras | G106: 4
A107: english_dp_underground_name_plural_classified | B107: UNDERGROUND_NAME_400 | E107: TM01s | G107: 4
A108: english_dp_underground_name_plural_classified | B108: UNDERGROUND_NAME_401 | E108: TM02s | G108: 4
A109: english_dp_underground_name_plural_classified | B109: UNDERGROUND_NAME_402 | E109: TM03s | G109: 4
A110: english_dp_underground_name_plural_classified | B110: UNDERGROUND_NAME_403 | E110: TM04s | G110: 4
A111: english_dp_underground_name_plural_classified | B111: UNDERGROUND_NAME_404 | E111: TM05s | G111: 4
A112: english_dp_underground_name_plural_classified | B112: UNDERGROUND_NAME_405 | E112: TM06s | G112: 4
A113: english_dp_underground_name_plural_classified | B113: UNDERGROUND_NAME_406 | E113: TM07s | G113: 4
A114: english_dp_underground_name_plural_classified | B114: UNDERGROUND_NAME_407 | E114: TM08s | G114: 4
A115: english_dp_underground_name_plural_classified | B115: UNDERGROUND_NAME_408 | E115: TM09s | G115: 4
A116: english_dp_underground_name_plural_classified | B116: UNDERGROUND_NAME_409 | E116: TM10s | G116: 4
A117: english_dp_underground_name_plural_classified | B117: UNDERGROUND_NAME_410 | E117: TM11s | G117: 4
A118: english_dp_underground_name_plural_classified | B118: UNDERGROUND_NAME_411 | E118: TM12s | G118: 4
... A198: english_dp_underground_name_plural_classified | B198: UNDERGROUND_NAME_491 | E198: TM92s | G198: 4
A199: english_dp_underground_name_plural_classified | B199: UNDERGROUND_NAME_492 | E199: Bulbasaur Statues | F199: Estátuas de Bulbasauro | G199: 2
A200: english_dp_underground_name_plural_classified | B200: UNDERGROUND_NAME_493 | E200: Ivysaur Statues | F200: Estátuas de Ivysauro | G200: 2
A201: english_dp_underground_name_plural_classified | B201: UNDERGROUND_NAME_494 | E201: Venusaur Statues | F201: Estátuas de Venusauro | G201: 2
A202: english_dp_underground_name_plural_classified | B202: UNDERGROUND_NAME_495 | E202: Charmander Statues | F202: Estátuas de Charmander | G202: 2
A203: english_dp_underground_name_plural_classified | B203: UNDERGROUND_NAME_496 | E203: Charmeleon Statues | F203: Estátuas de Charmeleon | G203: 2
A204: english_dp_underground_name_plural_classified | B204: UNDERGROUND_NAME_497 | E204: Charizard Statues | F204: Estátuas de Charizard | G204: 2
A205: english_dp_underground_name_plural_classified | B205: UNDERGROUND_NAME_498 | E205: Squirtle Statues | F205: Estátuas de Squirtle | G205: 2
A206: english_dp_underground_name_plural_classified | B206: UNDERGROUND_NAME_499 | E206: Wartortle Statues | F206: Estátuas de Wartortle | G206: 2
A207: english_dp_underground_name_plural_classified | B207: UNDERGROUND_NAME_500 | E207: Blastoise Statues | F207: Estátuas de Blastoise | G207: 2
A208: english_dp_underground_name_plural_classified | B208: UNDERGROUND_NAME_501 | E208: Pikachu Statues | F208: Estátuas de Pikachu | G208: 2
A209: english_dp_underground_name_plural_classified | B209: UNDERGROUND_NAME_502 | E209: Nidoqueen Statues | F209: Estátuas de Nidoqueen | G209: 2
A210: english_dp_underground_name_plural_classified | B210: UNDERGROUND_NAME_503 | E210: Nidoking Statues | F210: Estátuas de Nidoking | G210: 2
... A621: english_dp_underground_name_plural_classified | B621: UNDERGROUND_NAME_1096 | E621: Rotom Statues  | F621: Estátuas de Rotom  | G621: 12
...

Sheet Menus & UI
A1: file | B1: label | C1: location | D1: speaker | E1: english | F1: translation | G1: uses
A2: english_ss_status | B2: SS_status_02 | E2: Lv. [0] | F2: Nv. [0] | G2: 11
A3: english_ss_status | B3: SS_status_03 | E3: Name | F3: Nome | G3: 3
A4: english_ss_status | B4: SS_status_06 | E4: Original Trainer | F4: Treinador Original | G4: 2
A5: english_ss_status | B5: SS_status_09 | E5: ID No. | F5: Nº ID | G5: 2
A6: english_ss_status | B6: SS_status_90 | E6: Pokédex No. | F6: Nº Pokédex | G6: 1
A7: english_ss_status | B7: SS_status_12 | E7: Current Exp. Points | F7: Pontos de Exp. atuais | G7: 1
A8: english_ss_status | B8: SS_status_15 | E8: Points needed to level up | F8: Pontos para subir de nível | G8: 1
A9: english_ss_status | B9: SS_status_20 | E9: Held Item | F9: Item Segurado | G9: 3
A10: english_ss_status | B10: SS_status_23 | E10: Held Item | F10: Item Segurado | G10: 1
A11: english_ss_status | B11: SS_status_24 | E11: Change Markings | F11: Mudar Marcações | G11: 1
A12: english_ss_status | B12: SS_status_25 | E12: Back | F12: Voltar | G12: 18
A13: english_ss_status | B13: SS_status_28 | E13: HP | F13: PS | G13: 5
... A1961: english_ss_pokedex | B1961: SS_pokedex_196 | E1961: 83.8 lbs. | F1961: 38,0 kg | G1961: 1

Sheet Descriptions
A1: file | B1: label | C1: location | D1: speaker | E1: english | F1: translation | G1: uses
A2: english_ss_trainermemo | B2: SS_trainermemo_001 | E2: This Pokémon is pretty <color=#F01E1EFF>Hardy</color> by nature. | F2: Este Pokémon tem uma natureza bem <color=#F01E1EFF>Destemida</color>. | G2: 1
A3: english_ss_trainermemo | B3: SS_trainermemo_002 | E3: This Pokémon is pretty <color=#F01E1EFF>Lonely</color> by nature. | F3: Este Pokémon tem uma natureza bem <color=#F01E1EFF>Solitária</color>. | G3: 1
A4: english_ss_trainermemo | B4: SS_trainermemo_003 | E4: This Pokémon is pretty <color=#F01E1EFF>Brave</color> by nature. | F4: Este Pokémon tem uma natureza bem <color=#F01E1EFF>Valente</color>. | G4: 1
A5: english_ss_trainermemo | B5: SS_trainermemo_004 | E5: This Pokémon is pretty <color=#F01E1EFF>Adamant</color> by nature. | F5: Este Pokémon tem uma natureza bem <color=#F01E1EFF>Rígida</color>. | G5: 1
A6: english_ss_trainermemo | B6: SS_trainermemo_005 | E6: This Pokémon is pretty <color=#F01E1EFF>Naughty</color> by nature. | F6: Este Pokémon tem uma natureza bem <color=#F01E1EFF>Teimosa</color>. | G6: 1
A7: english_ss_trainermemo | B7: SS_trainermemo_006 | E7: This Pokémon is pretty <color=#F01E1EFF>Bold</color> by nature. | F7: Este Pokémon tem uma natureza bem <color=#F01E1EFF>Corajosa</color>. | G7: 1
A8: english_ss_trainermemo | B8: SS_trainermemo_007 | E8: This Pokémon is pretty <color=#F01E1EFF>Docile</color> by nature. | F8: Este Pokémon tem uma natureza bem <color=#F01E1EFF>Dócil</color>. | G8: 1
A9: english_ss_trainermemo | B9: SS_trainermemo_008 | E9: This Pokémon is pretty <color=#F01E1EFF>Relaxed</color> by nature. | F9: Este Pokémon tem uma natureza bem <color=#F01E1EFF>Descontraída</color>. | G9: 1
A10: english_ss_trainermemo | B10: SS_trainermemo_009 | E10: This Pokémon is pretty <color=#F01E1EFF>Impish</color> by nature. | F10: Este Pokémon tem uma natureza bem <color=#F01E1EFF>Inquieta</color>. | G10: 1
A11: english_ss_trainermemo | B11: SS_trainermemo_010 | E11: This Pokémon is pretty <color=#F01E1EFF>Lax</color> by nature. | F11: Este Pokémon tem uma natureza bem <color=#F01E1EFF>Relaxada</color>. | G11: 1
A12: english_ss_trainermemo | B12: SS_trainermemo_011 | E12: This Pokémon is pretty <color=#F01E1EFF>Timid</color> by nature. | F12: Este Pokémon tem uma natureza bem <color=#F01E1EFF>Tímida</color>. | G12: 1
A13: english_ss_trainermemo | B13: SS_trainermemo_012 | E13: This Pokémon is pretty <color=#F01E1EFF>Hasty</color> by nature. | F13: Este Pokémon tem uma natureza bem <color=#F01E1EFF>Apressada</color>. | G13: 1
... A3512: english_dp_pokedex_pearl | B3512: DP_pokedex_pearl_264_001 | E3512: It uses its long tongue to taunt opponents. Once the opposition is enraged, this Pokémon hurls[p]itself at the opponent, tackling them forcefully. | F3512: Mostra sua língua comprida para provocar o oponente e, quando o alvo perde a cabeça de[p]raiva, joga-se contra ele em uma investida violenta. | G3512: 2

Sheet Dialogue
A1: file | B1: label | C1: location | D1: speaker | E1: english | F1: translation | G1: uses
A2: english_dp_contest | B2: DP_contest_000 | E2: Dummy message | F2: Mensagem de teste | G2: 1
A3: english_dp_contest | B3: DP_contest_688 | E3: Oh? It seems you don’t have a Pokémon that can enter a contest show.[p]Please come back with a Pokémon that knows a move that can be used in contest shows. | F3: Oh? Parece que você não tem nenhum Pokémon que possa participar de um Concurso.[p]Por favor, volte com um Pokémon que conheça um movimento válido para os Concursos. | G3: 1
A4: english_dp_contest | B4: DP_contest_032 | E4: That’s it, folks! All evaluations have been tallied and totaled! Which Pokémon will be crowned the[s]Star of the Show? Let’s announce the results! | F4: E é isso aí, pessoal! Todas as notas foram somadas e calculadas! Qual Pokémon será coroado a[s]Estrela do Show? Vamos aos resultados! | G4: 1
A5: english_dp_contest | B5: DP_contest_118 | E5: Coolness Contest | F5: Concurso de Carisma | G5: 3
A6: english_dp_contest | B6: DP_contest_119 | E6: Beauty Contest | F6: Concurso de Beleza | G6: 3
A7: english_dp_contest | B7: DP_contest_120 | E7: Cuteness Contest | F7: Concurso de Fofura | G7: 3
A8: english_dp_contest | B8: DP_contest_121 | E8: Cleverness Contest | F8: Concurso de Astúcia | G8: 3
A9: english_dp_contest | B9: DP_contest_122 | E9: Toughness Contest | F9: Concurso de Vigor | G9: 3
A10: english_dp_contest | B10: DP_contest_123 | E10: Normal Rank | F10: Ranque Normal | G10: 3
A11: english_dp_contest | B11: DP_contest_124 | E11: Great Rank | F11: Ranque Grande | G11: 3
A12: english_dp_contest | B12: DP_contest_125 | E12: Ultra Rank | F12: Ranque Ultra | G12: 3
A13: english_dp_contest | B13: DP_contest_126 | E13: Master Rank | F13: Ranque Mestre | G13: 3
... A205: english_dp_contest | B205: 00_msg_r212ar0101_msg_35 | E205: Oh, hey. Nice job, kiddo.[p]You met the requirement alright. But who said we have to keep promises![p]Fwahahaha... | F205: Ora, ora. Mandou bem, pirralh{o|a}.[p]Você cumpriu a nossa exigência direitinho. Mas quem disse que a gente cumpre promessas?[p]Fuahahaha... | G205: 2
A206: english_dp_trainer_msg_sub | B206: 35-msg_c01r0201_idol_01 | C206: Jubilife City | D206: idol | E206: More than singing! More than dancing! I love Pokémon! So, shall we battle? | F206: Mais do que cantar! Mais do que dançar! Eu amo Pokémon! E aí, vamos batalhar? | G206: 1
A207: english_dp_trainer_msg_sub | B207: 35-msg_c01r0201_idol_02 | C207: Jubilife City | D207: idol | E207: I’ll let you join my fan club if you can beat me! | F207: Deixo você entrar no meu fã-clube se me vencer! | G207: 2
A208: english_dp_trainer_msg_sub | B208: 35-msg_c01r0201_idol_03 | C208: Jubilife City | D208: idol | E208: Aww, that’s heartbreaking... I’m an idol, too... | F208: Ah, você partiu meu coração... E olha que sou uma idol... | G208: 1
A209: english_dp_trainer_msg_sub | B209: 35-msg_c01r0201_idol_04 | C209: Jubilife City | D209: idol | E209: Well, that’s me and my Pokémon! Thank you for being such a fan![p]Just so you know, our latest single is called “Jigglin’ Pokémon Wub”! | F209: Bom, esses somos eu e o meu Pokémon! Obrigada por ser tão fã![p]E só pra você saber, nosso single mais recente se chama 'Pokémon no Batidão'! | G209: 2
A210: english_dp_trainer_msg_sub | B210: 35-msg_c01r0201_reporter_01 | C210: Jubilife City | D210: reporter | E210: I’m working on a story. Can you battle me? | F210: Estou fazendo uma matéria. Pode batalhar comigo? | G210: 1
A211: english_dp_trainer_msg_sub | B211: 35-msg_c01r0201_reporter_02 | C211: Jubilife City | D211: reporter | E211: Join me for a live report! | F211: Participe da minha transmissão ao vivo! | G211: 1
A212: english_dp_trainer_msg_sub | B212: 35-msg_c01r0201_reporter_03 | C212: Jubilife City | D212: reporter | E212: Press coverage denied... But you’re so intriguing! | F212: Cobertura de imprensa negada... Mas você é tão intrigante! | G212: 1
A213: english_dp_trainer_msg_sub | B213: 35-msg_c01r0201_reporter_04 | C213: Jubilife City | D213: reporter | E213: Interviews are about taking the initiative. | F213: Em uma entrevista, o segredo é tomar a iniciativa. | G213: 2
A214: english_dp_trainer_msg_sub | B214: 35-msg_c01r0201_cameraman_01 | C214: Jubilife City | D214: cameraman | E214: I’ve spotted a charismatic Trainer! Is it OK to go for the scoop? | F214: Avistei um{|a} Treinador{|a} cheio de carisma! Posso registrar esse furo? | G214: 1
A215: english_dp_trainer_msg_sub | B215: 35-msg_c01r0201_cameraman_02 | C215: Jubilife City | D215: cameraman | E215: As a professional cameraman, I always go for the best shot! | F215: Como cinegrafista profissional, estou sempre em busca do melhor ângulo! | G215: 1
A216: english_dp_trainer_msg_sub | B216: 35-msg_c01r0201_cameraman_03 | C216: Jubilife City | D216: cameraman | E216: That’s a downer... I thought I’d found a Trainer and Pokémon who’d shine on camera. | F216: Que balde de água fria... Achei que tinha encontrado um{|a} Treinador{|a} e um Pokémon que brilhariam na tela. | G216: 1
A217: english_dp_trainer_msg_sub | B217: 35-msg_c01r0201_cameraman_04 | C217: Jubilife City | D217: cameraman | E217: The lively expressions on you and your Pokémon’s faces make for some great TV! | F217: As expressões cheias de vida no seu rosto e no do seu Pokémon rendem ótimas cenas pra TV! | G217: 2
... A430: english_dp_trainer_msg_sub | B430: 115-msg_l02r0101_0903b_04 | C430: Valor Lakefront | D430: 0903b | E430: Don’t fret, dear. If we take in too many calories, we can always work them off by battling! | F430: Não se preocupe, querido. Se consumirmos calorias demais, sempre podemos queimá-las batalhando! | G430: 1
A431: english_dp_trainer_msg_sub | B431: 1-ARTIST_03_TRMSG_FIGHT_LOSE | D431: Artist Ismael | E431: Does this mean I’m only talented as an artist? | F431: Isso significa que meu único talento é como artista? | G431: 1
A432: english_dp_trainer_msg_sub | B432: 1-SISTER_10_TRMSG_FIGHT_LOSE | D432: Beauty Gabriella | E432: You’re a lucky one... | F432: Você deu sorte... | G432: 1
A433: english_dp_trainer_msg_sub | B433: 1-PRINCE_06_TRMSG_FIGHT_LOSE | D433: Rich Boy Roman | E433: I never thought I’d lose at Father’s restaurant... | F433: Nunca pensei que perderia no restaurante do meu pai... | G433: 1
A434: english_dp_trainer_msg_sub | B434: 1-PRINCESS_04_TRMSG_FIGHT_LOSE | D434: Lady Kylie | E434: Oh... How could I lose at dear Papa’s restaurant? | F434: Oh... Como pude perder no restaurante do meu querido papai? | G434: 1
A435: english_dp_trainer_msg_sub | B435: 1-GENTLE_03_TRMSG_FIGHT_LOSE | D435: Gentleman Leonardo | E435: Ack! I lost... Check, please! | F435: Argh! Eu perdi... A conta, por favor! | G435: 1
A436: english_dp_trainer_msg_sub | B436: 1-MADAM_03_TRMSG_FIGHT_LOSE | D436: Madame Rebecca | E436: So young, and yet so strong! How very remarkable! | F436: Tão jovem, e ainda assim tão forte! Simplesmente notável! | G436: 1
A437: english_dp_trainer_msg_sub | B437: 1-COLLECTOR_10_TRMSG_FIGHT_LOSE | D437: Collector Eugene | E437: I don’t care if I lose. I’m still a happy guy. | F437: Não ligo se perdi. Continuo sendo um cara feliz. | G437: 1
A438: english_dp_trainer_msg_sub | B438: 1-AROMA_06_TRMSG_FIGHT_LOSE | D438: Aroma Lady Alison | E438: Waaah! You’re too much! | F438: Buááá! Você é demais pra mim! | G438: 1
A439: english_dp_trainer_msg_sub | B439: 1-SCHOOLB_06_TRMSG_FIGHT_LOSE | D439: School Kid Esteban | E439: Wow... You’re out there. | F439: Uau... Você é de outro mundo. | G439: 1
A440: english_dp_trainer_msg_sub | B440: 1-DAISUKIW_05_TRMSG_FIGHT_LOSE | D440: Poké Fan Meredith | E440: No one’s hurt? | F440: Ninguém se machucou? | G440: 1
A441: english_dp_trainer_msg_sub | B441: 1-VETERAN_11_TRMSG_FIGHT_LOSE | D441: Veteran Emanuel | E441: Tough, aren’t you...? | F441: Você é dur{ão|ona} na queda, hein...? | G441: 1
A442: english_dp_trainer_msg_sub | B442: 1-MINI_13_TRMSG_FIGHT_LOSE | D442: Lass Blythe | E442: I was with my dad, too... | F442: E olha que eu estava com o meu pai... | G442: 1
... A450: english_dp_trainer_msg_sub | B450: 1-SCHOOLG_04_TRMSG_FIGHT_LOSE | D450: School Kid Christine | E450: I like to study a lot. I thought I could win... | F450: Eu gosto muito de estudar. Achei que fosse vencer... | G450: 1
...

Sheet Battle
A1: file | B1: label | C1: location | D1: speaker | E1: english | F1: translation | G1: uses
A2: english_ss_shinka_demo | B2: SS_shinka_demo_01_01 | E2: What? | F2: O quê? | G2: 1
A3: english_ss_shinka_demo | B3: SS_shinka_demo_02_01 | E3: Huh? [0] stopped evolving! | F3: Hã? [0] parou de evoluir! | G3: 1
A4: english_ss_shinka_demo | B4: SS_shinka_demo_03_01 | E4: Congratulations! Your [0] evolved into [1]! | F4: Parabéns! Seu [0] evoluiu para [1]! | G4: 1
A5: english_ss_shinka_demo | B5: SS_shinka_demo_04_01 | E5: [0] learned [1]![e:4][e:1] | F5: [0] aprendeu [1]![e:4][e:1] | G5: 2
A6: english_ss_shinka_demo | B6: SS_shinka_demo_05_01 | E6: One...[w:0.19999998807907104]two...[w:0.19999998807907104]and...[w:0.19999998807907104][w:0.19999998807907104]ta-da![e:3][e:0][p][0] forgot [1]![p]And it learned [2] instead![e:4][e:1] | F6: Um...[w:0.19999998807907104]dois...[w:0.19999998807907104]e...[w:0.19999998807907104][w:0.19999998807907104]tcharam![e:3][e:0][p][0] esqueceu [1]![p]E aprendeu [2] no lugar![e:4][e:1] | G6: 2
A7: english_ss_shinka_demo | B7: SS_shinka_demo_06_01 | E7: [0] did not learn [1]. | F7: [0] não aprendeu [1]. | G7: 3
A8: english_ss_shinka_demo | B8: SS_shinka_demo_07_01 | E8: [0] wants to learn the move [1].[p]Should an old move be forgotten and replaced with [2]? | F8: [0] quer aprender o movimento [1].[p]Deseja esquecer um movimento antigo e substituí-lo por [2]? | G8: 1
A9: english_ss_shinka_demo | B9: SS_shinka_demo_10_01 | E9: Forget an old move | F9: Esquecer um movimento antigo | G9: 3
A10: english_ss_shinka_demo | B10: SS_shinka_demo_10_02 | E10: Keep old moves | F10: Manter os movimentos antigos | G10: 3
A11: english_ss_shinka_demo | B11: SS_shinka_demo_01_02 | E11: [0] is evolving! | F11: [0] está evoluindo! | G11: 1
A12: english_ss_btl_tower_main | B12: SS_btl_tower_main_000 | E12: Battle Tower | F12: Torre de Batalha | G12: 1
A13: english_ss_btl_tower_main | B13: SS_btl_tower_main_001 | E13: Single Battle | F13: Batalha Individual | G13: 2
... A110: english_ss_btl_state | B110: BTR_STATE_02_02 | E110: The rain weather condition. It boosts the power of Water-type moves and lowers the power of Fire-type moves. | F110: A condição climática de chuva. Aumenta o poder dos movimentos de tipo Água e reduz o poder dos movimentos de tipo Fogo. | G110: 1
A111: english_ss_btl_state | B111: BTR_STATE_03_01 | E111: Sandstorm | F111: {=INDEX(Names!$F$2637:$F$3443,MATCH(E111,Names!$E$2637:$E$3443,0))} -> Temp. de Areia | G111: 1
A112: english_ss_btl_state | B112: BTR_STATE_03_02 | E112: The sandstorm weather condition. At the end of each turn, it damages all Pokémon that are not Rock, Ground, or Steel types. It boosts the Sp. Def of Rock-type Pokémon. | F112: A condição climática de tempestade de areia. Ao final de cada turno, causa dano a todos os Pokémon que não sejam de tipo Pedra, Terrestre ou Aço. Aumenta a Def. Esp. dos Pokémon de tipo Pedra. | G112: 1
A113: english_ss_btl_state | B113: BTR_STATE_04_01 | E113: Hail | F113: {=INDEX(Names!$F$2637:$F$3443,MATCH(E113,Names!$E$2637:$E$3443,0))} -> Granizo | G113: 1
A114: english_ss_btl_state | B114: BTR_STATE_04_02 | E114: The hail weather condition. At the end of each turn, it damages all Pokémon that are not Ice types. | F114: A condição climática de granizo. Ao final de cada turno, causa dano a todos os Pokémon que não sejam de tipo Gelo. | G114: 1
A115: english_ss_btl_state | B115: BTR_STATE_08_01 | E115: Trick Room | F115: {=INDEX(Names!$F$2637:$F$3443,MATCH(E115,Names!$E$2637:$E$3443,0))} -> Sala dos Truques | G115: 1
A116: english_ss_btl_state | B116: BTR_STATE_08_02 | E116: Slower Pokémon get to move first for five turns. | F116: Por cinco turnos, os Pokémon mais lentos agem primeiro. | G116: 1
A117: english_ss_btl_state | B117: BTR_STATE_11_01 | E117: Critical Hit Boost | F117: Chance de Crítico Aumentada | G117: 1
A118: english_ss_btl_state | B118: BTR_STATE_11_02 | E118: The Pokémon is more likely to land critical hits. | F118: O Pokémon tem mais chances de acertar golpes críticos. | G118: 1
A119: english_ss_btl_state | B119: BTR_STATE_12_01 | E119: Confusion | F119: Confusão | G119: 1
A120: english_ss_btl_state | B120: BTR_STATE_12_02 | E120: The Pokémon may hurt itself in its confusion. The effect lasts for one to four turns. | F120: O Pokémon pode se ferir na confusão. O efeito dura de um a quatro turnos. | G120: 1
A121: english_ss_btl_state | B121: BTR_STATE_13_01 | E121: Infatuation | F121: Paixão | G121: 1
A122: english_ss_btl_state | B122: BTR_STATE_13_02 | E122: The Pokémon is less likely to unleash an attack on Pokémon of the opposite gender. | F122: O Pokémon tem menos chances de atacar Pokémon do gênero oposto. | G122: 1
A123: english_ss_btl_state | B123: BTR_STATE_05_01 | E123: Electric Terrain | F123: {=INDEX(Names!$F$2637:$F$3443,MATCH(E123,Names!$E$2637:$E$3443,0))} -> Terreno Elétrico | G123: 1
A124: english_ss_btl_state | B124: BTR_STATE_05_02 | E124: For five turns, Pokémon on the ground won’t fall asleep. The power of Electric-type moves is boosted. | F124: Por cinco turnos, os Pokémon no chão não adormecem. O poder dos movimentos de tipo Elétrico aumenta. | G124: 1
A125: english_ss_btl_state | B125: BTR_STATE_16_01 | E125: Encore | F125: {=INDEX(Names!$F$2637:$F$3443,MATCH(E125,Names!$E$2637:$E$3443,0))} -> Bis | G125: 1
A126: english_ss_btl_state | B126: BTR_STATE_16_02 | E126: Due to Encore, the Pokémon can use only [0] for three turns. | F126: ="Devido a "&F125&", o Pokémon só pode usar"&CHAR(10)&"[0] por três turnos." -> Devido a Bis, o Pokémon só pode usar [0] por três turnos. | G126: 1
A127: english_ss_btl_state | B127: BTR_STATE_17_01 | E127: No Ability | F127: Sem Habilidade | G127: 1
A128: english_ss_btl_state | B128: BTR_STATE_17_02 | E128: The Pokémon’s Ability loses its effect. | F128: A Habilidade do Pokémon perde o efeito. | G128: 1
A129: english_ss_btl_state | B129: BTR_STATE_18_01 | E129: Torment | F129: {=INDEX(Names!$F$2637:$F$3443,MATCH(E129,Names!$E$2637:$E$3443,0))} -> Tormento | G129: 1
A130: english_ss_btl_state | B130: BTR_STATE_18_02 | E130: The Pokémon can’t use the same move twice in a row. | F130: O Pokémon não pode usar o mesmo movimento duas vezes seguidas. | G130: 1
A131: english_ss_btl_state | B131: BTR_STATE_19_01 | E131: Tailwind | F131: {=INDEX(Names!$F$2637:$F$3443,MATCH(E131,Names!$E$2637:$E$3443,0))} -> Vento de Cauda | G131: 1
A132: english_ss_btl_state | B132: BTR_STATE_19_02 | E132: The Speed stats of a Pokémon and its allies are doubled for four turns. | F132: A Velocidade do Pokémon e de seus aliados é duplicada por quatro turnos. | G132: 1
A133: english_ss_btl_state | B133: BTR_STATE_21_01 | E133: Grudge | F133: {=INDEX(Names!$F$2637:$F$3443,MATCH(E133,Names!$E$2637:$E$3443,0))} -> Rancor | G133: 1
A134: english_ss_btl_state | B134: BTR_STATE_21_02 | E134: If the Pokémon faints by an opponent’s move, the PP of that move will be reduced to 0. | F134: Se o Pokémon desmaiar devido a um movimento do oponente, os PP desse movimento serão reduzidos a 0. | G134: 1
A135: english_ss_btl_state | B135: BTR_STATE_06_01 | E135: Grassy Terrain | F135: {=INDEX(Names!$F$2637:$F$3443,MATCH(E135,Names!$E$2637:$E$3443,0))} -> Terreno de Grama | G135: 1
A136: english_ss_btl_state | B136: BTR_STATE_06_02 | E136: For five turns, Pokémon on the ground will have a little HP restored at the end of each turn. The power of Grass-type moves is boosted. | F136: Por cinco turnos, os Pokémon no chão recuperam um pouco de PS ao final de cada turno. O poder dos movimentos de tipo Planta aumenta. | G136: 1
...

Sheet Credits & Misc
A1: file | B1: label | C1: location | D1: speaker | E1: english | F1: translation | G1: uses
A2: english_dlp_halloffame_demo | B2: DLP_halloffame_demo_015 | E2: Lv. [0] | F2: Nv. [0] | G2: 1
A3: english_dlp_halloffame_demo | B3: DLP_halloffame_demo_013 | E3: [0] ID: [1] Time: [2]:[3] | F3: [0] ID: [1] Tempo: [2]:[3] | G3: 1
A4: english_dlp_staff_list | B4: DLP_staff_list_001 | E4: Pokémon Brilliant Diamond | F4: Pokémon Diamante Brilhante | G4: 1
A5: english_dlp_staff_list | B5: DLP_staff_list_002 | E5: Pokémon Shining Pearl | F5: Pokémon Pérola Reluzente | G5: 1
A6: english_dlp_staff_list | B6: DLP_staff_list_003 | E6: STAFF | F6: EQUIPE | G6: 1
A7: english_dlp_staff_list | B7: DLP_staff_list_004 | E7: DIRECTOR | F7: DIREÇÃO | G7: 2
A8: english_dlp_staff_list | B8: DLP_staff_list_005 | E8: Yuichi Ueda | F8: Yuichi Ueda | G8: 1
A9: english_dlp_staff_list | B9: DLP_staff_list_007 | E9: Junichi Masuda | F9: Junichi Masuda | G9: 3
A10: english_dlp_staff_list | B10: DLP_staff_list_008 | E10: 3D GRAPHIC MANAGER | F10: GERÊNCIA DE GRÁFICOS 3D | G10: 1
A11: english_dlp_staff_list | B11: DLP_staff_list_009 | E11: Takahiro Mizutani | F11: Takahiro Mizutani | G11: 1
A12: english_dlp_staff_list | B12: DLP_staff_list_010 | E12: PROGRAM LEADER | F12: LIDERANÇA DE PROGRAMAÇÃO | G12: 1
A13: english_dlp_staff_list | B13: DLP_staff_list_011 | E13: Shinya Suda | F13: Shinya Suda | G13: 1
... A599: english_ss_zkn_weight | B599: ZKN_WEIGHT_000_000 | E599: ????.? lbs. | F599: ????,? kg | G599: 1
A600: english_ss_zkn_weight | B600: ZKN_WEIGHT_001_000 | E600: 15.2 lbs. | F600: =SUBSTITUTE(TEXT(VALUE(SUBSTITUTE(LEFT(E600,LEN(E600)-5),".",","))*45359237/100000000,"0.0"),".",",")&" kg" -> 6,9 kg | G600: 2
A601: english_ss_zkn_weight | B601: ZKN_WEIGHT_002_000 | E601: 28.7 lbs. | F601: =SUBSTITUTE(TEXT(VALUE(SUBSTITUTE(LEFT(E601,LEN(E601)-5),".",","))*45359237/100000000,"0.0"),".",",")&" kg" -> 13,0 kg | G601: 8
A602: english_ss_zkn_weight | B602: ZKN_WEIGHT_003_000 | E602: 220.5 lbs. | F602: =SUBSTITUTE(TEXT(VALUE(SUBSTITUTE(LEFT(E602,LEN(E602)-5),".",","))*45359237/100000000,"0.0"),".",",")&" kg" -> 100,0 kg | G602: 7
A603: english_ss_zkn_weight | B603: ZKN_WEIGHT_004_000 | E603: 18.7 lbs. | F603: =SUBSTITUTE(TEXT(VALUE(SUBSTITUTE(LEFT(E603,LEN(E603)-5),".",","))*45359237/100000000,"0.0"),".",",")&" kg" -> 8,5 kg | G603: 11
A604: english_ss_zkn_weight | B604: ZKN_WEIGHT_005_000 | E604: 41.9 lbs. | F604: =SUBSTITUTE(TEXT(VALUE(SUBSTITUTE(LEFT(E604,LEN(E604)-5),".",","))*45359237/100000000,"0.0"),".",",")&" kg" -> 19,0 kg | G604: 5
A605: english_ss_zkn_weight | B605: ZKN_WEIGHT_006_000 | E605: 199.5 lbs. | F605: =SUBSTITUTE(TEXT(VALUE(SUBSTITUTE(LEFT(E605,LEN(E605)-5),".",","))*45359237/100000000,"0.0"),".",",")&" kg" -> 90,5 kg | G605: 3
A606: english_ss_zkn_weight | B606: ZKN_WEIGHT_007_000 | E606: 19.8 lbs. | F606: =SUBSTITUTE(TEXT(VALUE(SUBSTITUTE(LEFT(E606,LEN(E606)-5),".",","))*45359237/100000000,"0.0"),".",",")&" kg" -> 9,0 kg | G606: 7
A607: english_ss_zkn_weight | B607: ZKN_WEIGHT_008_000 | E607: 49.6 lbs. | F607: =SUBSTITUTE(TEXT(VALUE(SUBSTITUTE(LEFT(E607,LEN(E607)-5),".",","))*45359237/100000000,"0.0"),".",",")&" kg" -> 22,5 kg | G607: 2
A608: english_ss_zkn_weight | B608: ZKN_WEIGHT_009_000 | E608: 188.5 lbs. | F608: =SUBSTITUTE(TEXT(VALUE(SUBSTITUTE(LEFT(E608,LEN(E608)-5),".",","))*45359237/100000000,"0.0"),".",",")&" kg" -> 85,5 kg | G608: 3
A609: english_ss_zkn_weight | B609: ZKN_WEIGHT_010_000 | E609: 6.4 lbs. | F609: =SUBSTITUTE(TEXT(VALUE(SUBSTITUTE(LEFT(E609,LEN(E609)-5),".",","))*45359237/100000000,"0.0"),".",",")&" kg" -> 2,9 kg | G609: 1
A610: english_ss_zkn_weight | B610: ZKN_WEIGHT_011_000 | E610: 21.8 lbs. | F610: =SUBSTITUTE(TEXT(VALUE(SUBSTITUTE(LEFT(E610,LEN(E610)-5),".",","))*45359237/100000000,"0.0"),".",",")&" kg" -> 9,9 kg | G610: 4
A611: english_ss_zkn_weight | B611: ZKN_WEIGHT_012_000 | E611: 70.5 lbs. | F611: =SUBSTITUTE(TEXT(VALUE(SUBSTITUTE(LEFT(E611,LEN(E611)-5),".",","))*45359237/100000000,"0.0"),".",",")&" kg" -> 32,0 kg | G611: 6
... A1081: english_ss_zkn_weight | B1081: ZKN_WEIGHT_898_002 | E1081: 118.2 lbs. | F1081: =SUBSTITUTE(TEXT(VALUE(SUBSTITUTE(LEFT(E1081,LEN(E1081)-5),".",","))*45359237/100000000,"0.0"),".",",")&" kg" -> 53,6 kg | G1081: 1

Sheet Verificação
A1: REVISÃO FINAL — TERMOS E INTEGRIDADE
A2: Aba | B2: Linhas | C2: Traduções vazias | D2: Erros | E2: [0] | F2: [1] | G2: [2] | H2: [3] | I2: [p] | J2: [s] | K2: </color> | L2: [4] | M2: [5] | N2: [6] | O2: [7] | P2: [8] | Q2: [9] | R2: <color= | S2: [e: | T2: [w:
A3: Menus & UI | B3: 1960 | C3: =COUNTIFS('Menus & UI'!E2:E1961,"<>",'Menus & UI'!F2:F1961,"") -> 0 | D3: =SUMPRODUCT(--ISERROR('Menus & UI'!F2:F1961)) -> 0 | E3: =SUMPRODUCT(--((LEN('Menus & UI'!$E$2:$E$1961)-LEN(SUBSTITUTE('Menus & UI'!$E$2:$E$1961,E$2,"")))<>(LEN('Menus & UI'!$F$2:$F$1961)-LEN(SUBSTITUTE('Menus & UI'!$F$2:$F$1961,E$2,""))))) -> 0 | F3: =SUMPRODUCT(--((LEN('Menus & UI'!$E$2:$E$1961)-LEN(SUBSTITUTE('Menus & UI'!$E$2:$E$1961,F$2,"")))<>(LEN('Menus & UI'!$F$2:$F$1961)-LEN(SUBSTITUTE('Menus & UI'!$F$2:$F$1961,F$2,""))))) -> 0 | G3: =SUMPRODUCT(--((LEN('Menus & UI'!$E$2:$E$1961)-LEN(SUBSTITUTE('Menus & UI'!$E$2:$E$1961,G$2,"")))<>(LEN('Menus & UI'!$F$2:$F$1961)-LEN(SUBSTITUTE('Menus & UI'!$F$2:$F$1961,G$2,""))))) -> 0 | H3: =SUMPRODUCT(--((LEN('Menus & UI'!$E$2:$E$1961)-LEN(SUBSTITUTE('Menus & UI'!$E$2:$E$1961,H$2,"")))<>(LEN('Menus & UI'!$F$2:$F$1961)-LEN(SUBSTITUTE('Menus & UI'!$F$2:$F$1961,H$2,""))))) -> 0 | I3: =SUMPRODUCT(--((LEN('Menus & UI'!$E$2:$E$1961)-LEN(SUBSTITUTE('Menus & UI'!$E$2:$E$1961,I$2,"")))<>(LEN('Menus & UI'!$F$2:$F$1961)-LEN(SUBSTITUTE('Menus & UI'!$F$2:$F$1961,I$2,""))))) -> 0 | J3: =SUMPRODUCT(--((LEN('Menus & UI'!$E$2:$E$1961)-LEN(SUBSTITUTE('Menus & UI'!$E$2:$E$1961,J$2,"")))<>(LEN('Menus & UI'!$F$2:$F$1961)-LEN(SUBSTITUTE('Menus & UI'!$F$2:$F$1961,J$2,""))))) -> 0 | K3: =SUMPRODUCT(--((LEN('Menus & UI'!$E$2:$E$1961)-LEN(SUBSTITUTE('Menus & UI'!$E$2:$E$1961,K$2,"")))<>(LEN('Menus & UI'!$F$2:$F$1961)-LEN(SUBSTITUTE('Menus & UI'!$F$2:$F$1961,K$2,""))))) -> 0 | L3: =SUMPRODUCT(--((LEN('Menus & UI'!$E$2:$E$1961)-LEN(SUBSTITUTE('Menus & UI'!$E$2:$E$1961,L$2,"")))<>(LEN('Menus & UI'!$F$2:$F$1961)-LEN(SUBSTITUTE('Menus & UI'!$F$2:$F$1961,L$2,""))))) -> 0 | ... T3: =SUMPRODUCT(--((LEN('Menus & UI'!$E$2:$E$1961)-LEN(SUBSTITUTE('Menus & UI'!$E$2:$E$1961,T$2,"")))<>(LEN('Menus & UI'!$F$2:$F$1961)-LEN(SUBSTITUTE('Menus & UI'!$F$2:$F$1961,T$2,""))))) -> 0
A4: Descriptions | B4: 3511 | C4: =COUNTIFS(Descriptions!E2:E3512,"<>",Descriptions!F2:F3512,"") -> 0 | D4: =SUMPRODUCT(--ISERROR(Descriptions!F2:F3512)) -> 0 | E4: =SUMPRODUCT(--((LEN(Descriptions!$E$2:$E$3512)-LEN(SUBSTITUTE(Descriptions!$E$2:$E$3512,E$2,"")))<>(LEN(Descriptions!$F$2:$F$3512)-LEN(SUBSTITUTE(Descriptions!$F$2:$F$3512,E$2,""))))) -> 0 | F4: =SUMPRODUCT(--((LEN(Descriptions!$E$2:$E$3512)-LEN(SUBSTITUTE(Descriptions!$E$2:$E$3512,F$2,"")))<>(LEN(Descriptions!$F$2:$F$3512)-LEN(SUBSTITUTE(Descriptions!$F$2:$F$3512,F$2,""))))) -> 0 | G4: =SUMPRODUCT(--((LEN(Descriptions!$E$2:$E$3512)-LEN(SUBSTITUTE(Descriptions!$E$2:$E$3512,G$2,"")))<>(LEN(Descriptions!$F$2:$F$3512)-LEN(SUBSTITUTE(Descriptions!$F$2:$F$3512,G$2,""))))) -> 0 | H4: =SUMPRODUCT(--((LEN(Descriptions!$E$2:$E$3512)-LEN(SUBSTITUTE(Descriptions!$E$2:$E$3512,H$2,"")))<>(LEN(Descriptions!$F$2:$F$3512)-LEN(SUBSTITUTE(Descriptions!$F$2:$F$3512,H$2,""))))) -> 0 | I4: =SUMPRODUCT(--((LEN(Descriptions!$E$2:$E$3512)-LEN(SUBSTITUTE(Descriptions!$E$2:$E$3512,I$2,"")))<>(LEN(Descriptions!$F$2:$F$3512)-LEN(SUBSTITUTE(Descriptions!$F$2:$F$3512,I$2,""))))) -> 0 | J4: =SUMPRODUCT(--((LEN(Descriptions!$E$2:$E$3512)-LEN(SUBSTITUTE(Descriptions!$E$2:$E$3512,J$2,"")))<>(LEN(Descriptions!$F$2:$F$3512)-LEN(SUBSTITUTE(Descriptions!$F$2:$F$3512,J$2,""))))) -> 0 | K4: =SUMPRODUCT(--((LEN(Descriptions!$E$2:$E$3512)-LEN(SUBSTITUTE(Descriptions!$E$2:$E$3512,K$2,"")))<>(LEN(Descriptions!$F$2:$F$3512)-LEN(SUBSTITUTE(Descriptions!$F$2:$F$3512,K$2,""))))) -> 0 | L4: =SUMPRODUCT(--((LEN(Descriptions!$E$2:$E$3512)-LEN(SUBSTITUTE(Descriptions!$E$2:$E$3512,L$2,"")))<>(LEN(Descriptions!$F$2:$F$3512)-LEN(SUBSTITUTE(Descriptions!$F$2:$F$3512,L$2,""))))) -> 0 | ... T4: =SUMPRODUCT(--((LEN(Descriptions!$E$2:$E$3512)-LEN(SUBSTITUTE(Descriptions!$E$2:$E$3512,T$2,"")))<>(LEN(Descriptions!$F$2:$F$3512)-LEN(SUBSTITUTE(Descriptions!$F$2:$F$3512,T$2,""))))) -> 0
A5: Dialogue | B5: 9613 | C5: =COUNTIFS(Dialogue!E2:E9614,"<>",Dialogue!F2:F9614,"") -> 0 | D5: =SUMPRODUCT(--ISERROR(Dialogue!F2:F9614)) -> 0 | E5: =SUMPRODUCT(--((LEN(Dialogue!$E$2:$E$9614)-LEN(SUBSTITUTE(Dialogue!$E$2:$E$9614,E$2,"")))<>(LEN(Dialogue!$F$2:$F$9614)-LEN(SUBSTITUTE(Dialogue!$F$2:$F$9614,E$2,""))))) -> 0 | F5: =SUMPRODUCT(--((LEN(Dialogue!$E$2:$E$9614)-LEN(SUBSTITUTE(Dialogue!$E$2:$E$9614,F$2,"")))<>(LEN(Dialogue!$F$2:$F$9614)-LEN(SUBSTITUTE(Dialogue!$F$2:$F$9614,F$2,""))))) -> 0 | G5: =SUMPRODUCT(--((LEN(Dialogue!$E$2:$E$9614)-LEN(SUBSTITUTE(Dialogue!$E$2:$E$9614,G$2,"")))<>(LEN(Dialogue!$F$2:$F$9614)-LEN(SUBSTITUTE(Dialogue!$F$2:$F$9614,G$2,""))))) -> 0 | H5: =SUMPRODUCT(--((LEN(Dialogue!$E$2:$E$9614)-LEN(SUBSTITUTE(Dialogue!$E$2:$E$9614,H$2,"")))<>(LEN(Dialogue!$F$2:$F$9614)-LEN(SUBSTITUTE(Dialogue!$F$2:$F$9614,H$2,""))))) -> 0 | I5: =SUMPRODUCT(--((LEN(Dialogue!$E$2:$E$9614)-LEN(SUBSTITUTE(Dialogue!$E$2:$E$9614,I$2,"")))<>(LEN(Dialogue!$F$2:$F$9614)-LEN(SUBSTITUTE(Dialogue!$F$2:$F$9614,I$2,""))))) -> 0 | J5: =SUMPRODUCT(--((LEN(Dialogue!$E$2:$E$9614)-LEN(SUBSTITUTE(Dialogue!$E$2:$E$9614,J$2,"")))<>(LEN(Dialogue!$F$2:$F$9614)-LEN(SUBSTITUTE(Dialogue!$F$2:$F$9614,J$2,""))))) -> 0 | K5: =SUMPRODUCT(--((LEN(Dialogue!$E$2:$E$9614)-LEN(SUBSTITUTE(Dialogue!$E$2:$E$9614,K$2,"")))<>(LEN(Dialogue!$F$2:$F$9614)-LEN(SUBSTITUTE(Dialogue!$F$2:$F$9614,K$2,""))))) -> 0 | L5: =SUMPRODUCT(--((LEN(Dialogue!$E$2:$E$9614)-LEN(SUBSTITUTE(Dialogue!$E$2:$E$9614,L$2,"")))<>(LEN(Dialogue!$F$2:$F$9614)-LEN(SUBSTITUTE(Dialogue!$F$2:$F$9614,L$2,""))))) -> 0 | ... T5: =SUMPRODUCT(--((LEN(Dialogue!$E$2:$E$9614)-LEN(SUBSTITUTE(Dialogue!$E$2:$E$9614,T$2,"")))<>(LEN(Dialogue!$F$2:$F$9614)-LEN(SUBSTITUTE(Dialogue!$F$2:$F$9614,T$2,""))))) -> 0
A6: Battle | B6: 5350 | C6: =COUNTIFS(Battle!E2:E5351,"<>",Battle!F2:F5351,"") -> 0 | D6: =SUMPRODUCT(--ISERROR(Battle!F2:F5351)) -> 0 | E6: =SUMPRODUCT(--((LEN(Battle!$E$2:$E$5351)-LEN(SUBSTITUTE(Battle!$E$2:$E$5351,E$2,"")))<>(LEN(Battle!$F$2:$F$5351)-LEN(SUBSTITUTE(Battle!$F$2:$F$5351,E$2,""))))) -> 0 | F6: =SUMPRODUCT(--((LEN(Battle!$E$2:$E$5351)-LEN(SUBSTITUTE(Battle!$E$2:$E$5351,F$2,"")))<>(LEN(Battle!$F$2:$F$5351)-LEN(SUBSTITUTE(Battle!$F$2:$F$5351,F$2,""))))) -> 0 | G6: =SUMPRODUCT(--((LEN(Battle!$E$2:$E$5351)-LEN(SUBSTITUTE(Battle!$E$2:$E$5351,G$2,"")))<>(LEN(Battle!$F$2:$F$5351)-LEN(SUBSTITUTE(Battle!$F$2:$F$5351,G$2,""))))) -> 0 | H6: =SUMPRODUCT(--((LEN(Battle!$E$2:$E$5351)-LEN(SUBSTITUTE(Battle!$E$2:$E$5351,H$2,"")))<>(LEN(Battle!$F$2:$F$5351)-LEN(SUBSTITUTE(Battle!$F$2:$F$5351,H$2,""))))) -> 0 | I6: =SUMPRODUCT(--((LEN(Battle!$E$2:$E$5351)-LEN(SUBSTITUTE(Battle!$E$2:$E$5351,I$2,"")))<>(LEN(Battle!$F$2:$F$5351)-LEN(SUBSTITUTE(Battle!$F$2:$F$5351,I$2,""))))) -> 0 | J6: =SUMPRODUCT(--((LEN(Battle!$E$2:$E$5351)-LEN(SUBSTITUTE(Battle!$E$2:$E$5351,J$2,"")))<>(LEN(Battle!$F$2:$F$5351)-LEN(SUBSTITUTE(Battle!$F$2:$F$5351,J$2,""))))) -> 0 | K6: =SUMPRODUCT(--((LEN(Battle!$E$2:$E$5351)-LEN(SUBSTITUTE(Battle!$E$2:$E$5351,K$2,"")))<>(LEN(Battle!$F$2:$F$5351)-LEN(SUBSTITUTE(Battle!$F$2:$F$5351,K$2,""))))) -> 0 | L6: =SUMPRODUCT(--((LEN(Battle!$E$2:$E$5351)-LEN(SUBSTITUTE(Battle!$E$2:$E$5351,L$2,"")))<>(LEN(Battle!$F$2:$F$5351)-LEN(SUBSTITUTE(Battle!$F$2:$F$5351,L$2,""))))) -> 0 | ... T6: =SUMPRODUCT(--((LEN(Battle!$E$2:$E$5351)-LEN(SUBSTITUTE(Battle!$E$2:$E$5351,T$2,"")))<>(LEN(Battle!$F$2:$F$5351)-LEN(SUBSTITUTE(Battle!$F$2:$F$5351,T$2,""))))) -> 0
A7: Credits & Misc | B7: 1080 | C7: =COUNTIFS('Credits & Misc'!E2:E1081,"<>",'Credits & Misc'!F2:F1081,"") -> 0 | D7: =SUMPRODUCT(--ISERROR('Credits & Misc'!F2:F1081)) -> 0 | E7: =SUMPRODUCT(--((LEN('Credits & Misc'!$E$2:$E$1081)-LEN(SUBSTITUTE('Credits & Misc'!$E$2:$E$1081,E$2,"")))<>(LEN('Credits & Misc'!$F$2:$F$1081)-LEN(SUBSTITUTE('Credits & Misc'!$F$2:$F$1081,E$2,""))))) -> 0 | F7: =SUMPRODUCT(--((LEN('Credits & Misc'!$E$2:$E$1081)-LEN(SUBSTITUTE('Credits & Misc'!$E$2:$E$1081,F$2,"")))<>(LEN('Credits & Misc'!$F$2:$F$1081)-LEN(SUBSTITUTE('Credits & Misc'!$F$2:$F$1081,F$2,""))))) -> 0 | G7: =SUMPRODUCT(--((LEN('Credits & Misc'!$E$2:$E$1081)-LEN(SUBSTITUTE('Credits & Misc'!$E$2:$E$1081,G$2,"")))<>(LEN('Credits & Misc'!$F$2:$F$1081)-LEN(SUBSTITUTE('Credits & Misc'!$F$2:$F$1081,G$2,""))))) -> 0 | H7: =SUMPRODUCT(--((LEN('Credits & Misc'!$E$2:$E$1081)-LEN(SUBSTITUTE('Credits & Misc'!$E$2:$E$1081,H$2,"")))<>(LEN('Credits & Misc'!$F$2:$F$1081)-LEN(SUBSTITUTE('Credits & Misc'!$F$2:$F$1081,H$2,""))))) -> 0 | I7: =SUMPRODUCT(--((LEN('Credits & Misc'!$E$2:$E$1081)-LEN(SUBSTITUTE('Credits & Misc'!$E$2:$E$1081,I$2,"")))<>(LEN('Credits & Misc'!$F$2:$F$1081)-LEN(SUBSTITUTE('Credits & Misc'!$F$2:$F$1081,I$2,""))))) -> 0 | J7: =SUMPRODUCT(--((LEN('Credits & Misc'!$E$2:$E$1081)-LEN(SUBSTITUTE('Credits & Misc'!$E$2:$E$1081,J$2,"")))<>(LEN('Credits & Misc'!$F$2:$F$1081)-LEN(SUBSTITUTE('Credits & Misc'!$F$2:$F$1081,J$2,""))))) -> 0 | K7: =SUMPRODUCT(--((LEN('Credits & Misc'!$E$2:$E$1081)-LEN(SUBSTITUTE('Credits & Misc'!$E$2:$E$1081,K$2,"")))<>(LEN('Credits & Misc'!$F$2:$F$1081)-LEN(SUBSTITUTE('Credits & Misc'!$F$2:$F$1081,K$2,""))))) -> 0 | L7: =SUMPRODUCT(--((LEN('Credits & Misc'!$E$2:$E$1081)-LEN(SUBSTITUTE('Credits & Misc'!$E$2:$E$1081,L$2,"")))<>(LEN('Credits & Misc'!$F$2:$F$1081)-LEN(SUBSTITUTE('Credits & Misc'!$F$2:$F$1081,L$2,""))))) -> 0 | ... T7: =SUMPRODUCT(--((LEN('Credits & Misc'!$E$2:$E$1081)-LEN(SUBSTITUTE('Credits & Misc'!$E$2:$E$1081,T$2,"")))<>(LEN('Credits & Misc'!$F$2:$F$1081)-LEN(SUBSTITUTE('Credits & Misc'!$F$2:$F$1081,T$2,""))))) -> 0
A9: Marcadores: números indicam quantas linhas diferem do original na quantidade do marcador.
A10: Controles de marcadores verificam quantidades; a apresentação e os parâmetros completos ainda precisam de teste no jogo.
A11: Referências: Names e Página1; preservar nomes próprios e termos sem localização definida.
A12: Data da revisão: 2026-10-18
A14: Naturezas — divergências com Página1
A15: Names | B15: =SUMPRODUCT(--(Names!F3711:F3735<>'Página1'!M4:M28)) -> 25
A16: Menus & UI | B16: =SUMPRODUCT(--('Menus & UI'!F1243:F1267<>'Página1'!M4:M28)) -> 25
A17: Descriptions | B17: =SUMPRODUCT(--(Descriptions!F2:F26<>("Este Pokémon tem uma natureza bem <color=#F01E1EFF>"&'Página1'!M4:M28&"</color>."))) -> 25
A19: Linhas verificadas | B19: =SUM(B3:B7) -> 21514
A21: Correções: 212 traduções vazias em Battle; termos de itens, movimentos e locais; marcadores em Dialogue e Descriptions.
A22: Escopo: preenchimento, erros, quantidade dos marcadores listados e buscas terminológicas direcionadas. Não substitui teste visual no jogo.
A23: Resultado: nenhuma lacuna de tradução ou erro de célula; quantidades dos marcadores listados coincidem com o original.

Sheet Página1
A2: TWINLEAF TOWN | C2: VILA FOLHAPAR
A3: SANDGEM TOWN | C3: VILA FINAREIA
A4: JUBILIFE CITY | C4: CIDADE VIDALEGRE
A5: OREBURGH CITY | C5: CIDADE MINECÍPIO
A6: FLOAROMA TOWN | C6: VILA FLORAROMA
A7: ETERNA CITY | C7: CIDADE VELHENDA
A8: HEARTHOME CITY | C8: CIDADE DOCELAR
A9: SOLACEON TOWN | C9: VILA RUINIRVA
A10: VEILSTONE CITY | C10: CIDADE ROCHAVÉU
A11: PASTORIA CITY | C11: CIDADE PASTONAL
A12: CELESTIC TOWN | C12: VILA PROFECÉU
A13: CANALAVE CITY | C13: CIDADE CANALEITO
... A64: RAMANAS PARK | C64: PARQUE ROSA RUGOSA
